<robot name="leo_robot_1_ros2_shared">

  <!-- Base link -->
  <link name="base_link">
    <inertial>
      <mass value="1.584994" />
      <origin xyz="-0.019662 0.011643 -0.031802" />
      <inertia ixx="0.01042" ixy="0.001177" ixz="-0.0008871" iyy="0.01045" iyz="0.0002226" izz="0.01817" />
    </inertial>
    <visual>
      <geometry>
        <mesh filename="Chassis.dae" />
      </geometry>
    </visual>
    <collision>
      <geometry>
        <mesh filename="Chassis_outline.stl" />
      </geometry>
    </collision>
  </link>

  <!-- Rocker Left Link -->
  <link name="rocker_L_link">
    <inertial>
      <mass value="1.387336" />
      <origin xyz="0 0.01346 -0.06506" />
      <inertia ixx="0.002956" ixy="-0.000001489324" ixz="-0.000008103407" iyy="0.02924" iyz="0.00007112" izz="0.02832" />
    </inertial>
    <visual>
      <geometry>
        <mesh filename="Rocker.dae" />
      </geometry>
    </visual>
    <collision>
      <geometry>
        <mesh filename="Rocker_outline.stl" />
      </geometry>
    </collision>
  </link>

  <!-- Rocker Right Link -->
  <link name="rocker_R_link">
    <inertial>
      <mass value="1.387336" />
      <origin xyz="0 0.01346 -0.06506" />
      <inertia ixx="0.002956" ixy="-0.000001489324" ixz="-0.000008103407" iyy="0.02924" iyz="0.00007112" izz="0.02832" />
    </inertial>
    <visual>
      <geometry>
        <mesh filename="Rocker.dae" />
      </geometry>
    </visual>
    <collision>
      <geometry>
        <mesh filename="Rocker_outline.stl" />
      </geometry>
    </collision>
  </link>

  <!-- Wheel Front Left Link -->
  <link name="wheel_FL_link">
    <inertial>
      <mass value="0.283642" />
      <origin xyz="0 0.030026 0" />
      <inertia ixx="0.000391" ixy="0.00000123962" ixz="5.52582e-7" iyy="0.0004716" iyz="-0.000002082042" izz="0.000391" />
    </inertial>
    <visual>
      <geometry>
        <mesh filename="WheelA.dae" />
      </geometry>
    </visual>
    <collision>
      <origin rpy="1.5708 0 0" xyz="0 0 0" />
      <geometry>
        <cylinder length="0.07" radius="0.057" />
      </geometry>
    </collision>
    <collision>
      <origin rpy="1.5708 0 0" xyz="0 0 0" />
      <geometry>
        <cylinder length="0.04" radius="0.0625" />
      </geometry>
    </collision>
    <collision>
      <geometry>
        <mesh filename="Wheel_outline.stl" />
      </geometry>
    </collision>
  </link>

  <!-- Wheel Rear Left Link -->
  <link name="wheel_RL_link">
    <inertial>
      <mass value="0.283642" />
      <origin xyz="0 0.030026 0" />
      <inertia ixx="0.000391" ixy="0.00000123962" ixz="5.52582e-7" iyy="0.0004716" iyz="-0.000002082042" izz="0.000391" />
    </inertial>
    <visual>
      <geometry>
        <mesh filename="WheelA.dae" />
      </geometry>
    </visual>
    <collision>
      <origin rpy="1.5708 0 0" xyz="0 0 0" />
      <geometry>
        <cylinder length="0.07" radius="0.057" />
      </geometry>
    </collision>
    <collision>
      <origin rpy="1.5708 0 0" xyz="0 0 0" />
      <geometry>
        <cylinder length="0.04" radius="0.0625" />
      </geometry>
    </collision>
    <collision>
      <geometry>
        <mesh filename="Wheel_outline.stl" />
      </geometry>
    </collision>
  </link>

  <!-- Wheel Front Right Link -->
  <link name="wheel_FR_link">
    <inertial>
      <mass value="0.283642" />
      <origin xyz="0 0.030026 0" />
      <inertia ixx="0.000391" ixy="0.00000123962" ixz="5.52582e-7" iyy="0.0004716" iyz="-0.000002082042" izz="0.000391" />
    </inertial>
    <visual>
      <geometry>
        <mesh filename="WheelB.dae" />
      </geometry>
    </visual>
    <collision>
      <origin rpy="1.5708 0 0" xyz="0 0 0" />
      <geometry>
        <cylinder length="0.07" radius="0.057" />
      </geometry>
    </collision>
    <collision>
      <origin rpy="1.5708 0 0" xyz="0 0 0" />
      <geometry>
        <cylinder length="0.04" radius="0.0625" />
      </geometry>
    </collision>
    <collision>
      <geometry>
        <mesh filename="Wheel_outline.stl" />
      </geometry>
    </collision>
  </link>

  <!-- Wheel Rear Right Link -->
  <link name="wheel_RR_link">
    <inertial>
      <mass value="0.283642" />
      <origin xyz="0 0.030026 0" />
      <inertia ixx="0.000391" ixy="0.00000123962" ixz="5.52582e-7" iyy="0.0004716" iyz="-0.000002082042" izz="0.000391" />
    </inertial>
    <visual>
      <geometry>
        <mesh filename="WheelB.dae" />
      </geometry>
    </visual>
    <collision>
      <origin rpy="1.5708 0 0" xyz="0 0 0" />
      <geometry>
        <cylinder length="0.07" radius="0.057" />
      </geometry>
    </collision>
    <collision>
      <origin rpy="1.5708 0 0" xyz="0 0 0" />
      <geometry>
        <cylinder length="0.04" radius="0.0625" />
      </geometry>
    </collision>
    <collision>
      <geometry>
        <mesh filename="Wheel_outline.stl" />
      </geometry>
    </collision>
  </link>


  <!-- Joints -->

  <joint name="rocker_L_joint" type="fixed">
    <origin rpy="0 0 3.141592653589793" xyz="0.00263 0.14167 -0.04731" />
    <parent link="base_link" />
    <child link="rocker_L_link" />
    <axis xyz="0 1 0" />
    <limit effort="100.0" lower="-0.24" upper="0.24" velocity="100.0" />
    <dynamics damping="0.1" friction="1.0" />
  </joint>

  <joint name="rocker_R_joint" type="fixed">
    <origin rpy="0 0 0" xyz="0.00263 -0.14167 -0.04731" />
    <parent link="base_link" />
    <child link="rocker_R_link" />
    <axis xyz="0 1 0" />
    <limit effort="100.0" lower="-0.24" upper="0.24" velocity="100.0" />
    <dynamics damping="0.1" friction="1.0" />
    <mimic joint="rocker_L_joint" />
  </joint>

  <joint name="wheel_FL_joint" type="continuous">
    <origin rpy="0 0 0" xyz="-0.15256 -0.08214 -0.08802" />
    <parent link="rocker_L_link" />
    <child link="wheel_FL_link" />
    <axis xyz="0 -1 0" />
    <limit effort="2.0" velocity="6.0" />
    <dynamics damping="0.1" friction="0.3125" />
  </joint>
  <joint name="wheel_RL_joint" type="continuous">
    <origin rpy="0 0 0" xyz="0.15256 -0.08214 -0.08802" />
    <parent link="rocker_L_link" />
    <child link="wheel_RL_link" />
    <axis xyz="0 -1 0" />
    <limit effort="2.0" velocity="6.0" />
    <dynamics damping="0.1" friction="0.3125" />
  </joint>
  <joint name="wheel_FR_joint" type="continuous">
    <origin rpy="0 0 0" xyz="0.15256 -0.08214 -0.08802" />
    <parent link="rocker_R_link" />
    <child link="wheel_FR_link" />
    <axis xyz="0 1 0" />
    <limit effort="2.0" velocity="6.0" />
    <dynamics damping="0.1" friction="0.3125" />
  </joint>
  <joint name="wheel_RR_joint" type="continuous">
    <mimic joint="wheel_FL_joint" />
    <origin rpy="0 0 0" xyz="-0.15256 -0.08214 -0.08802" />
    <parent link="rocker_R_link" />
    <child link="wheel_RR_link" />
    <axis xyz="0 1 0" />
    <limit effort="2.0" velocity="6.0" />
    <dynamics damping="0.1" friction="0.3125" />
  </joint>



</robot>